Workbook
Name Arecord: INputs!$AD$3:$AD$6
Name color: INputs!$S$12:$S$22
Name emaillabel: INputs!$BB$3:$BB$5
Name encrypt: INputs!$AF$3:$AF$6
Name Groupsaccess: INputs!$AR$3:$AR$6
Name GroupsDef: INputs!$AN$3:$AN$6
Name Groupsshare: INputs!$AP$3:$AP$7
Name Label: INputs!$A$3:$A$7
Name LabelE: INputs!$M$24:$M$44
Name LabelG: INputs!$O$24:$O$44
Name LabelM: INputs!$N$24:$N$44
Name Lobby: INputs!$X$3:$X$10
Name meetchat: INputs!$AJ$3:$AJ$6
Name OutL: INputs!$V$3:$V$6
Name policy: INputs!$AZ$3:$AZ$8
Name Policymode: INputs!$AV$3:$AV$7
Name present: INputs!$Z$3:$Z$8
Name prevent: INputs!$AL$3:$AL$5
Name publabel: INputs!$AT$3:$AT$6
Name record: INputs!$AB$3:$AB$6
Name rules: INputs!$AX$3:$AX$5
Name Sens: INputs!$D$2:$D$22
Name sett: INputs!$S$3:$S$7
Name Slabel: INputs!$C$99:$T$106
Name SubL: INputs!$E$24:$E$44
Name Vlabel: INputs!$B$3:$C$22
Name WaterA: INputs!$AH$3:$AH$6
Name waterB: INputs!$AH$8:$AH$12

Sheet INputs
A1: ='Sensitivity Labels'!C1 -> Sensitivity Labels | C1: Sens | R1: Tab Location | S1: Emails | X1: Teams
H2: Group Check | I2: ='Sensitivity Labels'!G11 -> Files & Other Data assets | J2: ='Sensitivity Labels'!G13 -> Emails | K2: ='Sensitivity Labels'!G15 -> Meetings | L2: ='Sensitivity Labels'!G17 -> Groups & Sites | R2: List Name | S2: Settings | V2: ='Emails, Files, & Other Data'!U10 -> In outlook, enforce one of the following restrictions | X2: ='Teams meetings and chats'!D2 -> Control who can Bypass the Lobby: | Z2: ='Teams meetings and chats'!I2 -> Control Who Can Present: | AB2: ='Teams meetings and chats'!K2 -> Control who can Record and Transcribe: | AD2: ='Teams meetings and chats'!M2 -> Control Whether Meetings are Recorded Automatically: | AF2: ='Teams meetings and chats'!O2 -> Control End-to-end Encryption for Meeting Video and Audio: | AH2: ='Teams meetings and chats'!Q2 -> Control Watermarks: | AJ2: ='Teams meetings and chats'!W2 -> Control Meeting Chat: | AL2: ='Teams meetings and chats'!Y2 -> Prevent Copying and Forwarding of Meeting Content: | AN2: ='Groups & Sites'!H3 -> Define privacy and external user access settings: | AP2: ='Groups & Sites'!N13 -> Content can be shared with: | AR2: ='Groups & Sites'!P13 -> Use Microsoft Entra Conditional Access to protect labeled SharePoint sites | AT2: =Publishing!V3 -> Default settings for meetings and calendar events: | AV2: ='Service-side Auto-Labeling'!E2 -> Policy Mode | AX2: ='Service-side Auto-Labeling'!R2 -> Common or Advanced Rules: | AZ2: ='Data Loss Prevention (DLP)'!E3 -> Policy mode: | BB2: ='Emails, Files, & Other Data'!AB3 -> Auto-labeling for files and emails: "Client-side Auto-Labeling"
A3: Parent Label | B3: =G3 -> 1 | C3: =IF('Sensitivity Labels'!C11="","",'Sensitivity Labels'!C11) | D3: =IF('Sensitivity Labels'!D11="","",C3&"-"&'Sensitivity Labels'!D11) | E3: =IF(OR(C3="",(LEFT(D3,3)="Par"),RIGHT(C3,1)="p"),"",D3) | G3: 1 | H3: =IF(OR((LEFT(D3,3)="Par"),RIGHT(C3,1)="p"),"True","false") -> false | I3: ='Sensitivity Labels'!F11 -> FALSE | J3: ='Sensitivity Labels'!F13 -> FALSE | K3: ='Sensitivity Labels'!F15 -> FALSE | L3: ='Sensitivity Labels'!F17 -> FALSE | M3: =IF(D3="",P$3,IF(OR(I3=TRUE,J3=TRUE),D3,P$4)) -> Please fill out Sensitivity Labels Tab | N3: =IF(D3="",P$3,IF(AND(I3=TRUE,J3=TRUE,K3=TRUE),$D3,P$4)) -> Please fill out Sensitivity Labels Tab | O3: =IF(D3="",P$3,IF(L3=TRUE,$D3,P$4)) -> Please fill out Sensitivity Labels Tab | P3: Please fill out Sensitivity Labels Tab | R3: List Selection | S3: Control Access Control who can access and view labels | V3: Do not Forward | X3: Everyone | Z3: Everyone | AB3: Organizers and presenters | AD3: Record Automatically | AF3: Apply end-to-end encryption | AH3: Apply watermark to shared content | AJ3: On | AL3: Yes | AN3: Public | AP3: Anyone | AR3: Allow full access from desktop apps, mobile apps, and the web | AT3: Automatic apply highest priority label | AV3: On | AX3: Common Rules | AZ3: Run the policy in simulation mode | BB3: Automatically apply the label
A4: Label Group | B4: =G4 -> 2 | C4: =IF('Sensitivity Labels'!C19="","",'Sensitivity Labels'!C19) | D4: =IF('Sensitivity Labels'!D19="","",C4&"-"&'Sensitivity Labels'!D19) | E4: =IF(OR(C4="",(LEFT(D4,3)="Par"),RIGHT(C4,1)="p"),"",D4) | G4: =G3+1 -> 2 | H4: =IF(OR((LEFT(D4,3)="Par"),RIGHT(C4,1)="p"),"True","false") -> false | I4: ='Sensitivity Labels'!F19 -> FALSE | J4: ='Sensitivity Labels'!F21 -> FALSE | K4: ='Sensitivity Labels'!F23 -> FALSE | L4: ='Sensitivity Labels'!F25 -> FALSE | M4: =IF(D4="",P$3,IF(OR(I4=TRUE,J4=TRUE),D4,P$4)) -> Please fill out Sensitivity Labels Tab | N4: =IF(D4="",P$3,IF(AND(I4=TRUE,J4=TRUE,K4=TRUE),$D4,P$4)) -> Please fill out Sensitivity Labels Tab | O4: =IF(D4="",P$3,IF(L4=TRUE,$D4,P$4)) -> Please fill out Sensitivity Labels Tab | P4: Pending checkbox selection on Sensititivty Labels Tab | S4: Apply Content Marking | V4: Encrypt-Only | X4: People in my org, trusted orgs, and guests | Z4: People in my org and guests | AB4: Organizers and co-organizers | AD4: Don't record automatically | AF4: Don't apply end-to-end encryption | AH4: Don't apply watermark to shared content | AJ4: Off | AL4: No | AN4: Private | AP4: New and existing guests | AR4: Allow limited, web-only access | AT4: Recommend users apply the highest priority label | AV4: Simulation Mode | AX4: Advanced Rules | AZ4: Turn the policy on immediately | BB4: Recommend that users apply the label
A5: Label | B5: =G5 -> 3 | C5: =IF('Sensitivity Labels'!C27="","",'Sensitivity Labels'!C27) | D5: =IF('Sensitivity Labels'!D27="","",C5&"-"&'Sensitivity Labels'!D27) | E5: =IF(OR(C5="",(LEFT(D5,3)="Par"),RIGHT(C5,1)="p"),"",D5) | G5: =G4+1 -> 3 | H5: =IF(OR((LEFT(D5,3)="Par"),RIGHT(C5,1)="p"),"True","false") -> false | I5: ='Sensitivity Labels'!F27 -> FALSE | J5: ='Sensitivity Labels'!F29 -> FALSE | K5: ='Sensitivity Labels'!F31 -> FALSE | L5: ='Sensitivity Labels'!F33 -> FALSE | M5: =IF(D5="",P$3,IF(OR(I5=TRUE,J5=TRUE),D5,P$4)) -> Please fill out Sensitivity Labels Tab | N5: =IF(D5="",P$3,IF(AND(I5=TRUE,J5=TRUE,K5=TRUE),$D5,P$4)) -> Please fill out Sensitivity Labels Tab | O5: =IF(D5="",P$3,IF(L5=TRUE,$D5,P$4)) -> Please fill out Sensitivity Labels Tab | X5: People in my org and guests | Z5: Let meeting organizers select specific people | AJ5: In-Meeting Only | AN5: None | AP5: Existing Guests | AR5: Block Access | AT5: Do not inherit highest priority label from file | AV5: Simulation Mode with turn on if not modified in 7 days | AZ5: Leave the policy turned off
A6: Sub Label | B6: =G6 -> 4 | C6: =IF('Sensitivity Labels'!C35="","",'Sensitivity Labels'!C35) | D6: =IF('Sensitivity Labels'!D35="","",C6&"-"&'Sensitivity Labels'!D35) | E6: =IF(OR(C6="",(LEFT(D6,3)="Par"),RIGHT(C6,1)="p"),"",D6) | G6: =G5+1 -> 4 | H6: =IF(OR((LEFT(D6,3)="Par"),RIGHT(C6,1)="p"),"True","false") -> false | I6: ='Sensitivity Labels'!F35 -> FALSE | J6: ='Sensitivity Labels'!F37 -> FALSE | K6: ='Sensitivity Labels'!F39 -> FALSE | L6: ='Sensitivity Labels'!F41 -> FALSE | M6: =IF(D6="",P$3,IF(OR(I6=TRUE,J6=TRUE),D6,P$4)) -> Please fill out Sensitivity Labels Tab | N6: =IF(D6="",P$3,IF(AND(I6=TRUE,J6=TRUE,K6=TRUE),$D6,P$4)) -> Please fill out Sensitivity Labels Tab | O6: =IF(D6="",P$3,IF(L6=TRUE,$D6,P$4)) -> Please fill out Sensitivity Labels Tab | X6: People in my org | Z6: Only Organizers and co-organizers | AP6: Only People in your organizations | AV6: Off | AZ6: On
B7: =G7 -> 5 | C7: =IF('Sensitivity Labels'!C43="","",'Sensitivity Labels'!C43) | D7: =IF('Sensitivity Labels'!D43="","",C7&"-"&'Sensitivity Labels'!D43) | E7: =IF(OR(C7="",(LEFT(D7,3)="Par"),RIGHT(C7,1)="p"),"",D7) | G7: =G6+1 -> 5 | H7: =IF(OR((LEFT(D7,3)="Par"),RIGHT(C7,1)="p"),"True","false") -> false | I7: ='Sensitivity Labels'!F43 -> FALSE | J7: ='Sensitivity Labels'!F45 -> FALSE | K7: ='Sensitivity Labels'!F47 -> FALSE | L7: ='Sensitivity Labels'!F49 -> FALSE | M7: =IF(D7="",P$3,IF(OR(I7=TRUE,J7=TRUE),D7,P$4)) -> Please fill out Sensitivity Labels Tab | N7: =IF(D7="",P$3,IF(AND(I7=TRUE,J7=TRUE,K7=TRUE),$D7,P$4)) -> Please fill out Sensitivity Labels Tab | O7: =IF(D7="",P$3,IF(L7=TRUE,$D7,P$4)) -> Please fill out Sensitivity Labels Tab | X7: People who were invited
B8: =G8 -> 6 | C8: =IF('Sensitivity Labels'!C51="","",'Sensitivity Labels'!C51) | D8: =IF('Sensitivity Labels'!D51="","",C8&"-"&'Sensitivity Labels'!D51) | E8: =IF(OR(C8="",(LEFT(D8,3)="Par"),RIGHT(C8,1)="p"),"",D8) | G8: =G7+1 -> 6 | H8: =IF(OR((LEFT(D8,3)="Par"),RIGHT(C8,1)="p"),"True","false") -> false | I8: ='Sensitivity Labels'!F51 -> FALSE | J8: ='Sensitivity Labels'!F53 -> FALSE | K8: ='Sensitivity Labels'!F55 -> FALSE | L8: ='Sensitivity Labels'!F57 -> FALSE | M8: =IF(D8="",P$3,IF(OR(I8=TRUE,J8=TRUE),D8,P$4)) -> Please fill out Sensitivity Labels Tab | N8: =IF(D8="",P$3,IF(AND(I8=TRUE,J8=TRUE,K8=TRUE),$D8,P$4)) -> Please fill out Sensitivity Labels Tab | O8: =IF(D8="",P$3,IF(L8=TRUE,$D8,P$4)) -> Please fill out Sensitivity Labels Tab | X8: Only Organizers and co-organizers | AH8: Apply watermark to everyone's video feed
B9: =G9 -> 7 | C9: =IF('Sensitivity Labels'!C59="","",'Sensitivity Labels'!C59) | D9: =IF('Sensitivity Labels'!D59="","",C9&"-"&'Sensitivity Labels'!D59) | E9: =IF(OR(C9="",(LEFT(D9,3)="Par"),RIGHT(C9,1)="p"),"",D9) | G9: =G8+1 -> 7 | H9: =IF(OR((LEFT(D9,3)="Par"),RIGHT(C9,1)="p"),"True","false") -> false | I9: ='Sensitivity Labels'!F59 -> FALSE | J9: ='Sensitivity Labels'!F61 -> FALSE | K9: ='Sensitivity Labels'!F63 -> FALSE | L9: ='Sensitivity Labels'!F65 -> FALSE | M9: =IF(D9="",P$3,IF(OR(I9=TRUE,J9=TRUE),D9,P$4)) -> Please fill out Sensitivity Labels Tab | N9: =IF(D9="",P$3,IF(AND(I9=TRUE,J9=TRUE,K9=TRUE),$D9,P$4)) -> Please fill out Sensitivity Labels Tab | O9: =IF(D9="",P$3,IF(L9=TRUE,$D9,P$4)) -> Please fill out Sensitivity Labels Tab | AH9: Don't apply watermark to everyone's video feed
B10: =G10 -> 8 | C10: =IF('Sensitivity Labels'!C67="","",'Sensitivity Labels'!C67) | D10: =IF('Sensitivity Labels'!D67="","",C10&"-"&'Sensitivity Labels'!D67) | E10: =IF(OR(C10="",(LEFT(D10,3)="Par"),RIGHT(C10,1)="p"),"",D10) | G10: =G9+1 -> 8 | H10: =IF(OR((LEFT(D10,3)="Par"),RIGHT(C10,1)="p"),"True","false") -> false | I10: ='Sensitivity Labels'!F67 -> FALSE | J10: ='Sensitivity Labels'!F69 -> FALSE | K10: ='Sensitivity Labels'!F71 -> FALSE | L10: ='Sensitivity Labels'!F73 -> FALSE | M10: =IF(D10="",P$3,IF(OR(I10=TRUE,J10=TRUE),D10,P$4)) -> Please fill out Sensitivity Labels Tab | N10: =IF(D10="",P$3,IF(AND(I10=TRUE,J10=TRUE,K10=TRUE),$D10,P$4)) -> Please fill out Sensitivity Labels Tab | O10: =IF(D10="",P$3,IF(L10=TRUE,$D10,P$4)) -> Please fill out Sensitivity Labels Tab
B11: =G11 -> 9 | C11: =IF('Sensitivity Labels'!C75="","",'Sensitivity Labels'!C75) | D11: =IF('Sensitivity Labels'!D75="","",C11&"-"&'Sensitivity Labels'!D75) | E11: =IF(OR(C11="",(LEFT(D11,3)="Par"),RIGHT(C11,1)="p"),"",D11) | G11: =G10+1 -> 9 | H11: =IF(OR((LEFT(D11,3)="Par"),RIGHT(C11,1)="p"),"True","false") -> false | I11: ='Sensitivity Labels'!F75 -> FALSE | J11: ='Sensitivity Labels'!F77 -> FALSE | K11: ='Sensitivity Labels'!F79 -> FALSE | L11: ='Sensitivity Labels'!F81 -> FALSE | M11: =IF(D11="",P$3,IF(OR(I11=TRUE,J11=TRUE),D11,P$4)) -> Please fill out Sensitivity Labels Tab | N11: =IF(D11="",P$3,IF(AND(I11=TRUE,J11=TRUE,K11=TRUE),$D11,P$4)) -> Please fill out Sensitivity Labels Tab | O11: =IF(D11="",P$3,IF(L11=TRUE,$D11,P$4)) -> Please fill out Sensitivity Labels Tab | S11: Color
B12: =G12 -> 10 | C12: =IF('Sensitivity Labels'!C83="","",'Sensitivity Labels'!C83) | D12: =IF('Sensitivity Labels'!D83="","",C12&"-"&'Sensitivity Labels'!D83) | E12: =IF(OR(C12="",(LEFT(D12,3)="Par"),RIGHT(C12,1)="p"),"",D12) | G12: =G11+1 -> 10 | H12: =IF(OR((LEFT(D12,3)="Par"),RIGHT(C12,1)="p"),"True","false") -> false | I12: ='Sensitivity Labels'!F83 -> FALSE | J12: ='Sensitivity Labels'!F85 -> FALSE | K12: ='Sensitivity Labels'!F87 -> FALSE | L12: ='Sensitivity Labels'!F89 -> FALSE | M12: =IF(D12="",P$3,IF(OR(I12=TRUE,J12=TRUE),D12,P$4)) -> Please fill out Sensitivity Labels Tab | N12: =IF(D12="",P$3,IF(AND(I12=TRUE,J12=TRUE,K12=TRUE),$D12,P$4)) -> Please fill out Sensitivity Labels Tab | O12: =IF(D12="",P$3,IF(L12=TRUE,$D12,P$4)) -> Please fill out Sensitivity Labels Tab | S12: Black
B13: =G13 -> 11 | C13: =IF('Sensitivity Labels'!C91="","",'Sensitivity Labels'!C91) | D13: =IF('Sensitivity Labels'!D91="","",C13&"-"&'Sensitivity Labels'!D91) | E13: =IF(OR(C13="",(LEFT(D13,3)="Par"),RIGHT(C13,1)="p"),"",D13) | G13: =G12+1 -> 11 | H13: =IF(OR((LEFT(D13,3)="Par"),RIGHT(C13,1)="p"),"True","false") -> false | I13: ='Sensitivity Labels'!F91 -> FALSE | J13: ='Sensitivity Labels'!F93 -> FALSE | K13: ='Sensitivity Labels'!F95 -> FALSE | L13: ='Sensitivity Labels'!F97 -> FALSE | M13: =IF(D13="",P$3,IF(OR(I13=TRUE,J13=TRUE),D13,P$4)) -> Please fill out Sensitivity Labels Tab | N13: =IF(D13="",P$3,IF(AND(I13=TRUE,J13=TRUE,K13=TRUE),$D13,P$4)) -> Please fill out Sensitivity Labels Tab | O13: =IF(D13="",P$3,IF(L13=TRUE,$D13,P$4)) -> Please fill out Sensitivity Labels Tab | S13: Gray
B14: =G14 -> 12 | C14: =IF('Sensitivity Labels'!C99="","",'Sensitivity Labels'!C99) | D14: =IF('Sensitivity Labels'!D99="","",C14&"-"&'Sensitivity Labels'!D99) | E14: =IF(OR(C14="",(LEFT(D14,3)="Par"),RIGHT(C14,1)="p"),"",D14) | G14: =G13+1 -> 12 | H14: =IF(OR((LEFT(D14,3)="Par"),RIGHT(C14,1)="p"),"True","false") -> false | I14: ='Sensitivity Labels'!F99 -> FALSE | J14: ='Sensitivity Labels'!F101 -> FALSE | K14: ='Sensitivity Labels'!F103 -> FALSE | L14: ='Sensitivity Labels'!F105 -> FALSE | M14: =IF(D14="",P$3,IF(OR(I14=TRUE,J14=TRUE),D14,P$4)) -> Please fill out Sensitivity Labels Tab | N14: =IF(D14="",P$3,IF(AND(I14=TRUE,J14=TRUE,K14=TRUE),$D14,P$4)) -> Please fill out Sensitivity Labels Tab | O14: =IF(D14="",P$3,IF(L14=TRUE,$D14,P$4)) -> Please fill out Sensitivity Labels Tab | S14: Dark Gray
B15: =G15 -> 13 | C15: =IF('Sensitivity Labels'!C107="","",'Sensitivity Labels'!C107) | D15: =IF('Sensitivity Labels'!D107="","",C15&"-"&'Sensitivity Labels'!D107) | E15: =IF(OR(C15="",(LEFT(D15,3)="Par"),RIGHT(C15,1)="p"),"",D15) | G15: =G14+1 -> 13 | H15: =IF(OR((LEFT(D15,3)="Par"),RIGHT(C15,1)="p"),"True","false") -> false | I15: ='Sensitivity Labels'!F107 -> FALSE | J15: ='Sensitivity Labels'!F109 -> FALSE | K15: ='Sensitivity Labels'!F111 -> FALSE | L15: ='Sensitivity Labels'!F113 -> FALSE | M15: =IF(D15="",P$3,IF(OR(I15=TRUE,J15=TRUE),D15,P$4)) -> Please fill out Sensitivity Labels Tab | N15: =IF(D15="",P$3,IF(AND(I15=TRUE,J15=TRUE,K15=TRUE),$D15,P$4)) -> Please fill out Sensitivity Labels Tab | O15: =IF(D15="",P$3,IF(L15=TRUE,$D15,P$4)) -> Please fill out Sensitivity Labels Tab | S15: Magenta
B16: =G16 -> 14 | C16: =IF('Sensitivity Labels'!C115="","",'Sensitivity Labels'!C115) | D16: =IF('Sensitivity Labels'!D115="","",C16&"-"&'Sensitivity Labels'!D115) | E16: =IF(OR(C16="",(LEFT(D16,3)="Par"),RIGHT(C16,1)="p"),"",D16) | G16: =G15+1 -> 14 | H16: =IF(OR((LEFT(D16,3)="Par"),RIGHT(C16,1)="p"),"True","false") -> false | I16: ='Sensitivity Labels'!F115 -> FALSE | J16: ='Sensitivity Labels'!F117 -> FALSE | K16: ='Sensitivity Labels'!F119 -> FALSE | L16: ='Sensitivity Labels'!F121 -> FALSE | M16: =IF(D16="",P$3,IF(OR(I16=TRUE,J16=TRUE),D16,P$4)) -> Please fill out Sensitivity Labels Tab | N16: =IF(D16="",P$3,IF(AND(I16=TRUE,J16=TRUE,K16=TRUE),$D16,P$4)) -> Please fill out Sensitivity Labels Tab | O16: =IF(D16="",P$3,IF(L16=TRUE,$D16,P$4)) -> Please fill out Sensitivity Labels Tab | S16: Purple
B17: =G17 -> 15 | C17: =IF('Sensitivity Labels'!C123="","",'Sensitivity Labels'!C123) | D17: =IF('Sensitivity Labels'!D123="","",C17&"-"&'Sensitivity Labels'!D123) | E17: =IF(OR(C17="",(LEFT(D17,3)="Par"),RIGHT(C17,1)="p"),"",D17) | G17: =G16+1 -> 15 | H17: =IF(OR((LEFT(D17,3)="Par"),RIGHT(C17,1)="p"),"True","false") -> false | I17: ='Sensitivity Labels'!F123 -> FALSE | J17: ='Sensitivity Labels'!F125 -> FALSE | K17: ='Sensitivity Labels'!F127 -> FALSE | L17: ='Sensitivity Labels'!F129 -> FALSE | M17: =IF(D17="",P$3,IF(OR(I17=TRUE,J17=TRUE),D17,P$4)) -> Please fill out Sensitivity Labels Tab | N17: =IF(D17="",P$3,IF(AND(I17=TRUE,J17=TRUE,K17=TRUE),$D17,P$4)) -> Please fill out Sensitivity Labels Tab | O17: =IF(D17="",P$3,IF(L17=TRUE,$D17,P$4)) -> Please fill out Sensitivity Labels Tab | S17: Blue
B18: =G18 -> 16 | C18: =IF('Sensitivity Labels'!C131="","",'Sensitivity Labels'!C131) | D18: =IF('Sensitivity Labels'!D131="","",C18&"-"&'Sensitivity Labels'!D131) | E18: =IF(OR(C18="",(LEFT(D18,3)="Par"),RIGHT(C18,1)="p"),"",D18) | G18: =G17+1 -> 16 | H18: =IF(OR((LEFT(D18,3)="Par"),RIGHT(C18,1)="p"),"True","false") -> false | I18: ='Sensitivity Labels'!F131 -> FALSE | J18: ='Sensitivity Labels'!F133 -> FALSE | K18: ='Sensitivity Labels'!F135 -> FALSE | L18: ='Sensitivity Labels'!F137 -> FALSE | M18: =IF(D18="",P$3,IF(OR(I18=TRUE,J18=TRUE),D18,P$4)) -> Please fill out Sensitivity Labels Tab | N18: =IF(D18="",P$3,IF(AND(I18=TRUE,J18=TRUE,K18=TRUE),$D18,P$4)) -> Please fill out Sensitivity Labels Tab | O18: =IF(D18="",P$3,IF(L18=TRUE,$D18,P$4)) -> Please fill out Sensitivity Labels Tab | S18: Green
B19: =G19 -> 17 | C19: =IF('Sensitivity Labels'!C139="","",'Sensitivity Labels'!C139) | D19: =IF('Sensitivity Labels'!D139="","",C19&"-"&'Sensitivity Labels'!D139) | E19: =IF(OR(C19="",(LEFT(D19,3)="Par"),RIGHT(C19,1)="p"),"",D19) | G19: =G18+1 -> 17 | H19: =IF(OR((LEFT(D19,3)="Par"),RIGHT(C19,1)="p"),"True","false") -> false | I19: ='Sensitivity Labels'!F139 -> FALSE | J19: ='Sensitivity Labels'!F141 -> FALSE | K19: ='Sensitivity Labels'!F143 -> FALSE | L19: ='Sensitivity Labels'!F145 -> FALSE | M19: =IF(D19="",P$3,IF(OR(I19=TRUE,J19=TRUE),D19,P$4)) -> Please fill out Sensitivity Labels Tab | N19: =IF(D19="",P$3,IF(AND(I19=TRUE,J19=TRUE,K19=TRUE),$D19,P$4)) -> Please fill out Sensitivity Labels Tab | O19: =IF(D19="",P$3,IF(L19=TRUE,$D19,P$4)) -> Please fill out Sensitivity Labels Tab | S19: Amber
B20: =G20 -> 18 | C20: =IF('Sensitivity Labels'!C147="","",'Sensitivity Labels'!C147) | D20: =IF('Sensitivity Labels'!D147="","",C20&"-"&'Sensitivity Labels'!D147) | E20: =IF(OR(C20="",(LEFT(D20,3)="Par"),RIGHT(C20,1)="p"),"",D20) | G20: =G19+1 -> 18 | H20: =IF(OR((LEFT(D20,3)="Par"),RIGHT(C20,1)="p"),"True","false") -> false | I20: ='Sensitivity Labels'!F147 -> FALSE | J20: ='Sensitivity Labels'!F149 -> FALSE | K20: ='Sensitivity Labels'!F151 -> FALSE | L20: ='Sensitivity Labels'!F153 -> FALSE | M20: =IF(D20="",P$3,IF(OR(I20=TRUE,J20=TRUE),D20,P$4)) -> Please fill out Sensitivity Labels Tab | N20: =IF(D20="",P$3,IF(AND(I20=TRUE,J20=TRUE,K20=TRUE),$D20,P$4)) -> Please fill out Sensitivity Labels Tab | O20: =IF(D20="",P$3,IF(L20=TRUE,$D20,P$4)) -> Please fill out Sensitivity Labels Tab | S20: Orange
B21: =G21 -> 19 | C21: =IF('Sensitivity Labels'!C155="","",'Sensitivity Labels'!C155) | D21: =IF('Sensitivity Labels'!D155="","",C21&"-"&'Sensitivity Labels'!D155) | E21: =IF(OR(C21="",(LEFT(D21,3)="Par"),RIGHT(C21,1)="p"),"",D21) | G21: =G20+1 -> 19 | H21: =IF(OR((LEFT(D21,3)="Par"),RIGHT(C21,1)="p"),"True","false") -> false | I21: ='Sensitivity Labels'!F155 -> FALSE | J21: ='Sensitivity Labels'!F157 -> FALSE | K21: ='Sensitivity Labels'!F159 -> FALSE | L21: ='Sensitivity Labels'!F161 -> FALSE | M21: =IF(D21="",P$3,IF(OR(I21=TRUE,J21=TRUE),D21,P$4)) -> Please fill out Sensitivity Labels Tab | N21: =IF(D21="",P$3,IF(AND(I21=TRUE,J21=TRUE,K21=TRUE),$D21,P$4)) -> Please fill out Sensitivity Labels Tab | O21: =IF(D21="",P$3,IF(L21=TRUE,$D21,P$4)) -> Please fill out Sensitivity Labels Tab | S21: Brown
B22: =G22 -> 20 | C22: =IF('Sensitivity Labels'!C163="","",'Sensitivity Labels'!C163) | D22: =IF('Sensitivity Labels'!D163="","",C22&"-"&'Sensitivity Labels'!D163) | E22: =IF(OR(C22="",(LEFT(D22,3)="Par"),RIGHT(C22,1)="p"),"",D22) | G22: =G21+1 -> 20 | H22: =IF(OR((LEFT(D22,3)="Par"),RIGHT(C22,1)="p"),"True","false") -> false | I22: ='Sensitivity Labels'!F163 -> FALSE | J22: ='Sensitivity Labels'!F165 -> FALSE | K22: ='Sensitivity Labels'!F167 -> FALSE | L22: ='Sensitivity Labels'!F169 -> FALSE | M22: =IF(D22="",P$3,IF(OR(I22=TRUE,J22=TRUE),D22,P$4)) -> Please fill out Sensitivity Labels Tab | N22: =IF(D22="",P$3,IF(AND(I22=TRUE,J22=TRUE,K22=TRUE),$D22,P$4)) -> Please fill out Sensitivity Labels Tab | O22: =IF(D22="",P$3,IF(L22=TRUE,$D22,P$4)) -> Please fill out Sensitivity Labels Tab
E23: SubL | M23: LabelE | N23: LabelM | O23: LabelG
E24: {=IFERROR(_xlfn._xlws.FILTER(E3:E22,E3:E22<>""),"Please fill out Sensitivity Labels Tab")} -> Please fill out Sensitivity Labels Tab | M24: {=IFERROR(_xlfn._xlws.FILTER(M3:M22,M3:M22<>""),"Please fill out Sensitivity Labels Tab")} -> Please fill out Sensitivity Labels Tab | N24: {=IFERROR(_xlfn._xlws.FILTER(N3:N22,N3:N22<>""),"Please fill out Sensitivity Labels Tab")} -> Please fill out Sensitivity Labels Tab | O24: {=IFERROR(_xlfn._xlws.FILTER(O3:O22,O3:O22<>""),"Please fill out Sensitivity Labels Tab")} -> Please fill out Sensitivity Labels Tab
M25: Please fill out Sensitivity Labels Tab | N25: Please fill out Sensitivity Labels Tab | O25: Please fill out Sensitivity Labels Tab | R25: 1
M26: Please fill out Sensitivity Labels Tab | N26: Please fill out Sensitivity Labels Tab | O26: Please fill out Sensitivity Labels Tab | R26: =R25+1 -> 2
M27: Please fill out Sensitivity Labels Tab | N27: Please fill out Sensitivity Labels Tab | O27: Please fill out Sensitivity Labels Tab | R27: =R26+1 -> 3
M28: Please fill out Sensitivity Labels Tab | N28: Please fill out Sensitivity Labels Tab | O28: Please fill out Sensitivity Labels Tab | R28: =R27+1 -> 4
M29: Please fill out Sensitivity Labels Tab | N29: Please fill out Sensitivity Labels Tab | O29: Please fill out Sensitivity Labels Tab | R29: =R28+1 -> 5
M30: Please fill out Sensitivity Labels Tab | N30: Please fill out Sensitivity Labels Tab | O30: Please fill out Sensitivity Labels Tab | R30: =R29+1 -> 6
M31: Please fill out Sensitivity Labels Tab | N31: Please fill out Sensitivity Labels Tab | O31: Please fill out Sensitivity Labels Tab | R31: =R30+1 -> 7
M32: Please fill out Sensitivity Labels Tab | N32: Please fill out Sensitivity Labels Tab | O32: Please fill out Sensitivity Labels Tab | R32: =R31+1 -> 8
M33: Please fill out Sensitivity Labels Tab | N33: Please fill out Sensitivity Labels Tab | O33: Please fill out Sensitivity Labels Tab | R33: =R32+1 -> 9
M34: Please fill out Sensitivity Labels Tab | N34: Please fill out Sensitivity Labels Tab | O34: Please fill out Sensitivity Labels Tab | R34: =R33+1 -> 10
M35: Please fill out Sensitivity Labels Tab | N35: Please fill out Sensitivity Labels Tab | O35: Please fill out Sensitivity Labels Tab | R35: =R34+1 -> 11
M36: Please fill out Sensitivity Labels Tab | N36: Please fill out Sensitivity Labels Tab | O36: Please fill out Sensitivity Labels Tab | R36: =R35+1 -> 12
M37: Please fill out Sensitivity Labels Tab | N37: Please fill out Sensitivity Labels Tab | O37: Please fill out Sensitivity Labels Tab | R37: =R36+1 -> 13
... M43: Please fill out Sensitivity Labels Tab | N43: Please fill out Sensitivity Labels Tab | O43: Please fill out Sensitivity Labels Tab | R43: =R42+1 -> 19
R44: =R43+1 -> 20

Sheet How to Use
A1: This tool is meant to help you with planning and implementing your Sensitivity Labels. The pages below go together if they're colored the same. Further explanations below. | B1: MIT License Copyright (c) 2025 Nick Bear & Thomas Reed Permission is hereby granted, free of charge, to any person obtaining a copy of this software and associated documentation files (the "Software"), to deal in the Software without restriction, including without limitation the rights to use, copy, modify, merge, publish, distribute, sublicense, and/or sell copies of the Software, and to permit persons to whom the Software is furnished to do so, subject to the following conditions: The above copyright notice and this permission notice shall be included in all copies or substantial portions of the Software. THE SOFTWARE IS PROVIDED "AS IS", WITHOUT WARRANTY OF ANY KIND, EXPRESS OR IMPLIED, INCLUDING BUT NOT LIMITED TO THE WARRANTIES OF MERCHANTABILITY, FITNESS FOR A PARTICULAR PURPOSE AND NONINFRINGEMENT. IN NO EVENT SHALL THE AUTHORS OR COPYRIGHT HOLDERS BE LIABLE FOR ANY CLAIM, DAMAGES OR OTHER LIABILITY, WHETHER IN AN ACTION OF CONTRACT, TORT OR OTHERWISE, ARISING FROM, OUT OF OR IN CONNECTION WITH THE SOFTWARE OR THE USE OR OTHER DEALINGS IN THE SOFTWARE.
A3: Secure by default with Microsoft Purview | B3: https://learn.microsoft.com/en-us/purview/deploymentmodels/depmod-securebydefault-phase1
A4: Enabling "Groups & Sites" functionality to Sensitivity Labels | B4: https://www.linkedin.com/pulse/how-enable-container-based-groups-sites-sensitivity-label-bear-pberc/
A6: Legend:
A7: Page: | B7: Page Description: | C7: Microsoft Description: | D7: Links:
A8: Sensitivity Labels | B8: This the overview of your "Labels", what are "Parent" labels or "Sub" labels, "Priority" order, and what they're "Scoped" to. Since Sensitivity Labels can have different functionality based on where they're "Scoped" to we broke each section out into the following (Blue) pages even though we configure them in the same place for ease of understanding. Pay close attention to the big numbers on the left of each page. Under "Scope" here the corresponding “Scope box” MUST be selected with a “Label or Sub-Label” selected for it to be available in the same big number in “Emails, Files, & Other Data Assets, Teams meetings and chats, Groups & Sites” tabs. The Big numbers on the left side of each page can be referenced in the "Search" tab. | C8: Sensitivity labels are used to classify email messages, documents, sites, and more. When a label is applied (automatically or by the user), the content or site is protected based on the settings you choose. For example, you can create labels that encrypt files, add content marking, and control user access to specific sites. Labels can be applied to data assets and containers (like SharePoint sites and Teams). Let us know where you want this label to be used so we can show you the related protection settings. | D8: Learn about sensitivity labels | Microsoft Learn
A10: Emails, Files, & Other Data Assets | B10: These are Sensitivity Label's settings for Object based labeling.
A12: Teams meetings and chats | B12: These are Sensitivity Label's settings for "Teams meetings and chats" labeling.
A14: Groups & Sites | B14: These are Sensitivity Label's settings for Container based labeling. | C14: These settings apply to teams, groups, and sites that have this label applied. They don't apply directly to the files stored in those containers. | D14: Use sensitivity labels with Microsoft Teams, Microsoft 365 Groups, and SharePoint sites | Microsoft Learn
A16: Summary | B16: This shows at a higher level the Sensitivity Label settings you have set for your Labels. This is meant for the use case of seeing a friendlier & easier way to read your labels. If you need specifics of the setting or label, then go to that label's functionality tab and check or use the "Search" tab and bring that label up.
A18: Publishing | B18: This shows who and what settings you are pushing out Sensitivity Labels to. The Big numbers on the left side of each page can be referenced in the "Search" tab. | C18: Publish one or more labels to users' Microsoft 365 apps (like Outlook and Word), SharePoint sites, and Microsoft 365 groups. Once published, users can apply the labels to protect their content. | D18: Learn about sensitivity labels | Microsoft Learn
A20: Service-side Auto-Labeling | B20: This shows what service (Exchange Online, SharePoint Online, OneDrive) locations and conditions you are using to target "Cold Data" to auto-label with a Sensitivity Label. The Big numbers on the left side of each page can be referenced in the "Search" tab. | C20: Automatically apply sensitivity labels to sensitive emails, files, and other data assets. In addition to these policies, you can automatically apply labels to Office client apps by editing the "Auto-labeling" settings for a specific label. | D20: Automatically apply a sensitivity label to Microsoft 365 data | Microsoft Learn
A22: Data Loss Prevention | B22: This is to show what Data Loss Prevention (DLP) policies you're using the Sensitivity Label with. The Big numbers on the left side of each page can be referenced in the "Search" tab. | C22: Use data loss prevention (DLP) policies to help identify and protect your organization's sensitive info. For example you can set up policies to help make sure information in email and docs isn't shared with the wrong people. | D22: Learn about data loss prevention | Microsoft Learn
A24: Search | B24: This is for you to be able to search the Label, Publishing, Service-side Auto-Labeling, and or Data Loss Prevention (DLP) policy you're looking for. You would use the boxes at the top with numbers which are drop downs to select the numbered Label and or Policies you wish to review the configurations of.

Sheet Sensitivity Labels
C1: Sensitivity Labels
C3: Label/Parent Label/Label Group/Sub-Label: | D3: Name: | E3: Display Name: | F3: Scope: | I3: Description for users: | J3: Description for admins: | K3: Label Color:
A4: Explanation | C4: You will Select if the label is going to be a "Label/Parent Label/Label Group/Sub-Label". ("Parent Label" will be depreciated and replaced with "Label Groups" when "modern label scheme" rolls out.) | D4: This is the name of the label your admins will see in the compliance portal when configuring or managing labels. (You cannot change or reuse this name, even if you delete the label.) | E4: This is the name of the label your users will see in the apps where it's published (like Word, Outlook, and SharePoint). Be sure to come with a name that helps them understand what it's used for (for example, 'Confidential' or 'Personal'). | F4: What are the Scopes for this label. What capabilities will the label have and settings in those areas. The areas that you select here you need to go to the appropriate tabs on the bottom and add the settings for that label there. The tabs are the same color (Blue) because they are meant to be directly used together. | I4: When this label is applied to content, this tooltip will appear to users when they view the label in their apps (like Word, Outlook, and Teams) | J4: This description will appear only to admins who manage this label in the Purview portal. | K4: The color selected below is currently applied to the parent label. As a result, all sublabels of the parent label will inherit the same color. If you want to use a different color, edit the parent label.
A5: Links | C5: Get started with sensitivity labels | F5: Label scopes | K5: Label colors
C6: Learn about sensitivity labels
C7: Migrate parent sensitivity labels to label groups
C8: Label priority (order matters)
C10: Select from Drop down | D10: Enter Text | E10: Enter Text | F10: Select check box as needed | I10: Enter Text | J10: Enter Text | K10: Choose from Drop Down
A11: 1 | B11: =A11+10 -> 11 | F11: FALSE | G11: Files & Other Data assets | H11: Label files and data assets in Microsoft 365, Microsoft Fabric (Including Power BI), Microsoft Azure
B12: =B11+1 -> 12
B13: =B12+1 -> 13 | F13: FALSE | G13: Emails | H13: Label Messages send from all versions of Outlook
B14: =B13+1 -> 14
B15: =B14+1 -> 15 | F15: FALSE | G15: Meetings | H15: Label Calendar events and meetings schedules in Outlook and Teams
B16: =B15+1 -> 16
B17: =B16+1 -> 17 | F17: FALSE | G17: Groups & Sites | H17: Configure privacy, access control, and other project team labeled Teams, Microsoft 365 Groups , SharePoint sites, and Loop
A19: 2 | B19: =B11+10 -> 21 | F19: FALSE | G19: Files & Other Data assets | H19: Label files and data assets in Microsoft 365, Microsoft Fabric (Including Power BI), Microsoft Azure
B20: =B19+1 -> 22
B21: =B20+1 -> 23 | F21: FALSE | G21: Emails | H21: Label Messages send from all versions of Outlook
B22: =B21+1 -> 24
B23: =B22+1 -> 25 | F23: FALSE | G23: Meetings | H23: Label Calendar events and meetings schedules in Outlook and Teams
B24: =B23+1 -> 26
B25: =B24+1 -> 27 | F25: FALSE | G25: Groups & Sites | H25: Configure privacy, access control, and other project team labeled Teams, Microsoft 365 Groups , SharePoint sites, and Loop
A27: 3 | B27: =B19+10 -> 31 | F27: FALSE | G27: Files & Other Data assets | H27: Label files and data assets in Microsoft 365, Microsoft Fabric (Including Power BI), Microsoft Azure
B28: =B27+1 -> 32
B29: =B28+1 -> 33 | F29: FALSE | G29: Emails | H29: Label Messages send from all versions of Outlook
B30: =B29+1 -> 34
B31: =B30+1 -> 35 | F31: FALSE | G31: Meetings | H31: Label Calendar events and meetings schedules in Outlook and Teams
B32: =B31+1 -> 36
B33: =B32+1 -> 37 | F33: FALSE | G33: Groups & Sites | H33: Configure privacy, access control, and other project team labeled Teams, Microsoft 365 Groups , SharePoint sites, and Loop
A35: 4 | B35: =B27+10 -> 41 | F35: FALSE | G35: Files & Other Data assets | H35: Label files and data assets in Microsoft 365, Microsoft Fabric (Including Power BI), Microsoft Azure
B36: =B35+1 -> 42
B37: =B36+1 -> 43 | F37: FALSE | G37: Emails | H37: Label Messages send from all versions of Outlook
B38: =B37+1 -> 44
B39: =B38+1 -> 45 | F39: FALSE | G39: Meetings | H39: Label Calendar events and meetings schedules in Outlook and Teams
B40: =B39+1 -> 46
B41: =B40+1 -> 47 | F41: FALSE | G41: Groups & Sites | H41: Configure privacy, access control, and other project team labeled Teams, Microsoft 365 Groups , SharePoint sites, and Loop
A43: 5 | B43: =B35+10 -> 51 | F43: FALSE | G43: Files & Other Data assets | H43: Label files and data assets in Microsoft 365, Microsoft Fabric (Including Power BI), Microsoft Azure
B44: =B43+1 -> 52
B45: =B44+1 -> 53 | F45: FALSE | G45: Emails | H45: Label Messages send from all versions of Outlook
B46: =B45+1 -> 54
...

Sheet Emails, Files, & Other Data
C1: Emails, Files, & Other Data Assets
H2: Access Control
C3: Label/Sub-Label Name: | E3: Choose protection settings for the types of items you selected: | H3: Remove or Configure: | J3: Assign: | L3: User access to content expires: | O3: Allow offline access: | R3: Assign Permissions Now: | U3: Let users assign permissions when they apply the label: | X3: Content Marking: | AB3: Auto-labeling for files and emails: "Client-side Auto-Labeling"
A4: Explanation | C4: Select the label/Sub-Label that these settings will be used for. | E4: Select the capabilities do you want this label to apply to "Emails, Files, & Other Data Assets". The protection settings you configure will be enforced when the label is applied to items in Microsoft 365. | H4: When you select Configure access control settings on the Access control page to create or edit a sensitivity label, choose one of the following options: | J4: Use encryption capabilities to control who can access labeled items. Depending on the scope you specified, items can include emails, Office, Fabric and Power BI files, and meeting invites. If the user applying the label has the correct usage rights or role, any existing access control settings will be removed from the item. | L4: If you want to limit how long users can access content with this label, specify a date or number of days at which access should expire. More info: After this time, users won't be able to open files with this label applied. However, for emails, expiration isn't always enforced due to caching mechanisms used by some email clients. If you specify a date, it's effective midnight, in your current time zone. If you specify a number of days, the time starts when the label is applied to the content. | O4: If you specify that labeled content is never available offline or that it's available offline only for a number of days, when that threshold is reached, users must be reauthenticated and their access is logged. When this happens, if their credentials aren't cached, users are prompted to sign into Microsoft 365 before they can open the document or email. | R4: Only the users or groups you choose will be assigned permissions to use the content that has this label applied. You can choose from existing permissions (such as Co-Owner, Co-Author, and Reviewer) or customize them to meet your needs. | U4: Often referred to as "user-defined permissions", you can use the following options to let users assign permissions when they manually apply a sensitivity label to content | X4: Add custom headers, footers, and watermarks to content that has this label applied. (All content marking will be applied to documents but only the header and footer will be applied to email messages. If you chose to configure meeting settings for this label, the header and footer will also be applied to meeting invites.) | AB4: When users edit Office files or compose, reply to, or forward emails from Outlook that contain content matching the conditions you choose here, we'll automatically apply this label or recommend that they apply it themselves. Automatic and recommended labeling works differently for items in Office 365 vs. files stored on Windows devices. (To automatically apply this label to files that are already saved (in SharePoint and OneDrive) or emails that are already processed by Exchange, you must create an auto-labeling policy.)
A5: Links | E5: Create and configure sensitivity labels | H5: Configure encryption settings | J5: Restrict access to content by using sensitivity labels to apply encryption | L5: Assign permissions now | O5: Assign permissions now | R5: Usage rights and descriptions | U5: Let users assign permissions | X5: What sensitivity labels can do | AB5: Automatically apply a sensitivity label to Microsoft 365 data
H6: How to configure a label for encryption | J6: What happens to existing encryption when a label's applied | O6: Rights Management use license for offline access | AB6: Service-Side Auto Labeling (Which is used on the Yellow tab of the same name.)
AB7: https://learn.microsoft.com/en-us/purview/apply-sensitivity-label-automatically#how-automatic-or-recommended-labels-are-applied
A10: 1 | B10: =A10+10 -> 11 | C10: =VLOOKUP(A10,INputs!$G$3:$O$22,7,FALSE) -> Please fill out Sensitivity Labels Tab | F10: Select check box as needed | H10: Select check box as needed | J10: Select a check box | L10: Select check box as needed | O10: Select check box as needed | R10: Assign Permissions to specific user and groups | T10: Enter Text | U10: In outlook, enforce one of the following restrictions | Y10: Select check box as needed | AE10: Enter Text (Detect content that matches these conditions)
B11: =B10+1 -> 12 | AC11: Select check box as needed
B12: =B11+1 -> 13 | E12: FALSE | F12: Control Access Control who can access and view labeled items. | H12: FALSE | I12: Remove access control settings if already applied to items | J12: FALSE | K12: Assign Permissions now | L12: FALSE | M12: Never | O12: FALSE | P12: Always | X12: FALSE | Y12: Add a watermark | AB12: FALSE | AC12: Auto-labeling for files and emails
B13: =B12+1 -> 14 | E13: FALSE | F13: Apply Content marking Add custom headers, footers, and watermarks to labeled items. | J13: FALSE | K13: Let users assign permissions when they apply the label | L13: FALSE | M13: On a specific Date | N13: 44197 | O13: FALSE | P13: Never | R13: FALSE | S13: Use dynamic watermarking | T13: Enter Text | U13: FALSE | V13: In Word, PowerPoint, and Excel, prompt users to specify Permissions | X13: FALSE | Y13: Add a header | AC13: Choose from Drop Down | AE13: Enter Text (Display this message to users when the label is applied)
B14: =B13+1 -> 15 | E14: FALSE | F14: Protect Team meetings and chats Configure protection settings for Teams meetings and chats. (Configure under the Teams Tab) | H14: FALSE | I14: Configure access control setting | L14: FALSE | M14: # of days after label is applied | N14: 78 | O14: FALSE | P14: # of days after label is applied | Q14: 76 | U14: Select check box as needed | X14: FALSE | Y14: Add a footer
B15: =B14+1 -> 16 | U15: FALSE | V15: Use dynamic watermarking
B16: =B15+1 -> 17 | R16: FALSE | S16: Use Double Key Encryption | T16: Enter Text
B17: =B16+1 -> 18 | U17: FALSE | V17: Use Double Key Encryption
B18: =B17+1 -> 19
A22: =A10+1 -> 2 | B22: =B10+10 -> 21 | C22: =VLOOKUP(A22,INputs!$G$3:$O$22,7,FALSE) -> Please fill out Sensitivity Labels Tab | F22: Select check box as needed | H22: Select check box as needed | J22: =J$10 -> Select a check box | L22: Select check box as needed | O22: Select check box as needed | R22: Assign Permissions to specific user and groups | T22: Enter Text | U22: In outlook, enforce one of the following restrictions | Y22: Select check box as needed | AE22: Enter Text (Detect content that matches these conditions)
B23: =B22+1 -> 22 | V23: Choose from Drop Down | AC23: Select check box as needed
B24: =B23+1 -> 23 | E24: FALSE | F24: Control Access Control who can access and view labeled items. | H24: FALSE | I24: Remove access control settings if already applied to items | J24: FALSE | K24: Assign Permissions now | L24: FALSE | M24: Never | O24: FALSE | P24: Always | X24: FALSE | Y24: Add a watermark | AB24: FALSE | AC24: Auto-labeling for files and emails
B25: =B24+1 -> 24 | E25: FALSE | F25: Apply Content marking Add custom headers, footers, and watermarks to labeled items. | J25: FALSE | K25: Let users assign permissions when they apply the label | L25: FALSE | M25: On a specific Date | N25: 44197 | O25: FALSE | P25: Never | R25: FALSE | S25: Use dynamic watermarking | T25: Enter Text | U25: FALSE | V25: In Word, PowerPoint, and Excel, prompt users to specify Permissions | X25: FALSE | Y25: Add a header | AC25: Choose from Drop Down | AE25: Enter Text (Display this message to users when the label is applied)
B26: =B25+1 -> 25 | E26: FALSE | F26: Protect Team meetings and chats Configure protection settings for Teams meetings and chats. (Configure under the Teams Tab) | H26: FALSE | I26: Configure access control setting | L26: FALSE | M26: # of days after label is applied | N26: 6 | O26: FALSE | P26: # of days after label is applied | Q26: 7 | U26: Select check box as needed | X26: FALSE | Y26: Add a footer
B27: =B26+1 -> 26 | U27: FALSE | V27: Use dynamic watermarking
B28: =B27+1 -> 27 | R28: FALSE | S28: Use Double Key Encryption | T28: Enter Text
B29: =B28+1 -> 28 | U29: FALSE | V29: Use Double Key Encryption
B30: =B29+1 -> 29
A34: =A22+1 -> 3 | B34: =B22+10 -> 31 | C34: =VLOOKUP(A34,INputs!$G$3:$O$22,7,FALSE) -> Please fill out Sensitivity Labels Tab | F34: Select check box as needed | H34: Select check box as needed | J34: =J10 -> Select a check box | L34: Select check box as needed | O34: Select check box as needed | R34: Assign Permissions to specific user and groups | T34: Enter Text | U34: In outlook, enforce one of the following restrictions | Y34: Select check box as needed | AE34: Enter Text (Detect content that matches these conditions)
B35: =B34+1 -> 32 | V35: Choose from Drop Down | AC35: Select check box as needed
B36: =B35+1 -> 33 | E36: FALSE | F36: Control Access Control who can access and view labeled items. | H36: FALSE | I36: Remove access control settings if already applied to items | J36: FALSE | K36: Assign Permissions now | L36: FALSE | M36: Never | O36: FALSE | P36: Always | X36: FALSE | Y36: Add a watermark | AB36: FALSE | AC36: Auto-labeling for files and emails
B37: =B36+1 -> 34 | E37: FALSE | F37: Apply Content marking Add custom headers, footers, and watermarks to labeled items. | J37: FALSE | K37: Let users assign permissions when they apply the label | L37: FALSE | M37: On a specific Date | N37: 44197 | O37: FALSE | P37: Never | R37: FALSE | S37: Use dynamic watermarking | T37: Enter Text | U37: FALSE | V37: In Word, PowerPoint, and Excel, prompt users to specify Permissions | X37: FALSE | Y37: Add a header | AC37: Choose from Drop Down | AE37: Enter Text (Display this message to users when the label is applied)
B38: =B37+1 -> 35 | E38: FALSE | F38: Protect Team meetings and chats Configure protection settings for Teams meetings and chats. (Configure under the Teams Tab) | H38: FALSE | I38: Configure access control setting | L38: FALSE | M38: # of days after label is applied | N38: 0 | O38: FALSE | P38: # of days after label is applied | Q38: 0 | U38: Select check box as needed | X38: FALSE | Y38: Add a footer
B39: =B38+1 -> 36 | U39: FALSE | V39: Use dynamic watermarking
B40: =B39+1 -> 37 | R40: FALSE | S40: Use Double Key Encryption | T40: Enter Text
B41: =B40+1 -> 38 | U41: FALSE | V41: Use Double Key Encryption
B42: =B41+1 -> 39
A46: =A34+1 -> 4 | B46: =B34+10 -> 41 | C46: =VLOOKUP(A46,INputs!$G$3:$O$22,7,FALSE) -> Please fill out Sensitivity Labels Tab | F46: Select check box as needed | H46: Select check box as needed | J46: =J10 -> Select a check box | L46: Select check box as needed | O46: Select check box as needed | R46: Assign Permissions to specific user and groups | T46: Enter Text | U46: In outlook, enforce one of the following restrictions | Y46: Select check box as needed | AE46: Enter Text (Detect content that matches these conditions)
B47: =B46+1 -> 42 | V47: Choose from Drop Down | AC47: Select check box as needed
B48: =B47+1 -> 43 | E48: FALSE | F48: Control Access Control who can access and view labeled items. | H48: FALSE | I48: Remove access control settings if already applied to items | J48: FALSE | K48: Assign Permissions now | L48: FALSE | M48: Never | O48: FALSE | P48: Always | X48: FALSE | Y48: Add a watermark | AB48: FALSE | AC48: Auto-labeling for files and emails
B49: =B48+1 -> 44 | E49: FALSE | F49: Apply Content marking Add custom headers, footers, and watermarks to labeled items. | J49: FALSE | K49: Let users assign permissions when they apply the label | L49: FALSE | M49: On a specific Date | N49: 44197 | O49: FALSE | P49: Never | R49: FALSE | S49: Use dynamic watermarking | T49: Enter Text | U49: FALSE | V49: In Word, PowerPoint, and Excel, prompt users to specify Permissions | X49: FALSE | Y49: Add a header | AC49: Choose from Drop Down | AE49: Enter Text (Display this message to users when the label is applied)
B50: =B49+1 -> 45 | E50: FALSE | F50: Protect Team meetings and chats Configure protection settings for Teams meetings and chats. (Configure under the Teams Tab) | H50: FALSE | I50: Configure access control setting | L50: FALSE | M50: # of days after label is applied | N50: 6 | O50: FALSE | P50: # of days after label is applied | Q50: 7 | U50: Select check box as needed | X50: FALSE | Y50: Add a footer
B51: =B50+1 -> 46 | U51: FALSE | V51: Use dynamic watermarking
...

Sheet Teams meetings and chats
B1: Teams meetings and chats
B2: Label/Sub-Label Name: | D2: Control who can Bypass the Lobby: | I2: Control Who Can Present: | K2: Control who can Record and Transcribe: | M2: Control Whether Meetings are Recorded Automatically: | O2: Control End-to-end Encryption for Meeting Video and Audio: | Q2: Control Watermarks: | U2: Detect sensitive content during screen sharing: | W2: Control Meeting Chat: | Y2: Prevent Copying and Forwarding of Meeting Content:
A3: Explanation | B3: Select the label/Sub-Label that these settings will be used for. | D3: Groups you specify here will be able to join meetings without having to wait for someone to admit them. All others will have to wait in the lobby until they're admitted or denied. Depending on the meeting policy set up by your IT admin, people joining without a Teams account, people from untrusted organizations, and people dialing in may be placed in the lobby until someone from your org or a trusted org joins the meeting, even if the 'Everyone' option is selected. | K3: If selected, you won't be able to record meetings automatically, apply end-to-end encryption, or apply watermarks. | M3: If selected, you won't be able to control who can record and transcribe, apply end-to-end encryption, or apply watermarks. | O3: End-to-end encryption in Teams is controlled by enhanced encryption policies, which are created in the Teams admin center. When a meeting is encrypted end-to-end, the policies might prevent some participants from joining. Not all features will be available, including recording, transcription, and live captions. If selected, you won't be able to record meetings automatically or control who can record and transcribe. | Q3: Watermarks aren't available for all scenarios, including recording, PowerPoint Live, and Whiteboard. Users joining from unsupported platforms can't see video or shared content. If selected, you won't be able to control who can record and transcribe or record meetings automatically. | U3: If selected, you won't be able to apply end-to-end encryption. | Y3: Meeting participants won't be able to copy or forward meeting chat messages, links, live captions, transcripts, or AI-generated content. However, there might be exceptions, like using screen capture or developer tools.
A4: Links | B4: Use sensitivity labels to protect calendar items, Teams meetings, and chat | D4: IT Admins - Manage lobby options in Microsoft Teams | Y4: Prevent copying and forwarding for chats and meeting content
D9: Choose from Drop Down | F9: Select check box as needed | I9: Choose from Drop Down | K9: Choose from Drop Down | M9: Choose from Drop Down | O9: Choose from Drop Down | Q9: Choose from Drop Down | S9: Choose from Drop Down | U9: Choose from Drop Down | W9: Choose from Drop Down | Y9: Choose from Drop Down
A11: 1 | B11: =VLOOKUP(A11,INputs!$G$3:$O$22,8,FALSE) -> Please fill out Sensitivity Labels Tab | F11: FALSE | G11: People dialing in can bypass the lobby
A13: 2 | B13: =VLOOKUP(A13,INputs!$G$3:$O$22,8,FALSE) -> Please fill out Sensitivity Labels Tab | F13: FALSE | G13: People dialing in can bypass the lobby
A15: 3 | B15: =VLOOKUP(A15,INputs!$G$3:$O$22,8,FALSE) -> Please fill out Sensitivity Labels Tab | F15: FALSE | G15: People dialing in can bypass the lobby
A17: 4 | B17: =VLOOKUP(A17,INputs!$G$3:$O$22,8,FALSE) -> Please fill out Sensitivity Labels Tab | F17: FALSE | G17: People dialing in can bypass the lobby
A19: 5 | B19: =VLOOKUP(A19,INputs!$G$3:$O$22,8,FALSE) -> Please fill out Sensitivity Labels Tab | F19: FALSE | G19: People dialing in can bypass the lobby
A21: 6 | B21: =VLOOKUP(A21,INputs!$G$3:$O$22,8,FALSE) -> Please fill out Sensitivity Labels Tab | F21: FALSE | G21: People dialing in can bypass the lobby
A23: 7 | B23: =VLOOKUP(A23,INputs!$G$3:$O$22,8,FALSE) -> Please fill out Sensitivity Labels Tab | F23: FALSE | G23: People dialing in can bypass the lobby
A25: 8 | B25: =VLOOKUP(A25,INputs!$G$3:$O$22,8,FALSE) -> Please fill out Sensitivity Labels Tab | F25: FALSE | G25: People dialing in can bypass the lobby
A27: 9 | B27: =VLOOKUP(A27,INputs!$G$3:$O$22,8,FALSE) -> Please fill out Sensitivity Labels Tab | F27: FALSE | G27: People dialing in can bypass the lobby
A29: 10 | B29: =VLOOKUP(A29,INputs!$G$3:$O$22,8,FALSE) -> Please fill out Sensitivity Labels Tab | F29: FALSE | G29: People dialing in can bypass the lobby
A31: =A29+1 -> 11 | B31: =VLOOKUP(A31,INputs!$G$3:$O$22,8,FALSE) -> Please fill out Sensitivity Labels Tab | F31: FALSE | G31: People dialing in can bypass the lobby
A33: =A31+1 -> 12 | B33: =VLOOKUP(A33,INputs!$G$3:$O$22,8,FALSE) -> Please fill out Sensitivity Labels Tab | F33: FALSE | G33: People dialing in can bypass the lobby
A35: =A33+1 -> 13 | B35: =VLOOKUP(A35,INputs!$G$3:$O$22,8,FALSE) -> Please fill out Sensitivity Labels Tab | F35: FALSE | G35: People dialing in can bypass the lobby
A37: =A35+1 -> 14 | B37: =VLOOKUP(A37,INputs!$G$3:$O$22,8,FALSE) -> Please fill out Sensitivity Labels Tab | F37: FALSE | G37: People dialing in can bypass the lobby
A39: =A37+1 -> 15 | B39: =VLOOKUP(A39,INputs!$G$3:$O$22,8,FALSE) -> Please fill out Sensitivity Labels Tab | F39: FALSE | G39: People dialing in can bypass the lobby
A41: =A39+1 -> 16 | B41: =VLOOKUP(A41,INputs!$G$3:$O$22,8,FALSE) -> Please fill out Sensitivity Labels Tab | F41: FALSE | G41: People dialing in can bypass the lobby
A43: =A41+1 -> 17 | B43: =VLOOKUP(A43,INputs!$G$3:$O$22,8,FALSE) -> Please fill out Sensitivity Labels Tab | F43: FALSE | G43: People dialing in can bypass the lobby
A45: =A43+1 -> 18 | B45: =VLOOKUP(A45,INputs!$G$3:$O$22,8,FALSE) -> Please fill out Sensitivity Labels Tab | F45: FALSE | G45: People dialing in can bypass the lobby
A47: =A45+1 -> 19 | B47: =VLOOKUP(A47,INputs!$G$3:$O$22,8,FALSE) -> Please fill out Sensitivity Labels Tab | F47: FALSE | G47: People dialing in can bypass the lobby
A49: =A47+1 -> 20 | B49: =VLOOKUP(A49,INputs!$G$3:$O$22,8,FALSE) -> Please fill out Sensitivity Labels Tab | F49: FALSE | G49: People dialing in can bypass the lobby

Sheet Groups & Sites
C1: Groups & Sites
C3: Label/Sub-Label Name: | E3: Define protection settings for groups and sites: | H3: Define privacy and external user access settings: | K3: External sharing and Conditional Access: | N3: External sharing: | P3: Conditional Access: | S3: Private teams discoverability and shared channel controls:
A4: Explanation | C4: Select the label/Sub-Label that these settings will be used for. | E4: These settings apply to teams, groups, and sites that have this label applied. They don't apply directly to the files stored in those containers. | H4: Control the level of access that internal and external users will have to labeled teams and Microsoft 365 Groups. These options apply to all Microsoft 365 Groups and teams that have this label applied. When applied, these settings will replace any existing privacy settings for the team or group. If the label is removed, users can change it again. | K4: Control who can share SharePoint content with people outside your organization and decide whether users can access labeled sites from unmanaged devices.​ | N4: When this label is applied to a SharePoint site, these settings will replace existing external sharing settings configured for the site. | P4: You can either control the level of access users have from unmanaged devices or select an existing authentication context to enforce restrictions. | S4: Decide whether labeled private teams will be discoverable in searches, and control how channels can be shared with other teams.
A5: Links | C5: Use sensitivity labels to protect content in Microsoft Teams, Microsoft 365 groups, and SharePoint sites | S5: Private teams discoverability and shared channel controls
E10: Select check box as needed | I10: Choose from Drop Down | L10: Select check box as needed | Q10: Select check box as needed | S10: Select check box as needed
A13: 1 | B13: =A13+10 -> 11 | C13: =VLOOKUP(A13,INputs!$G$3:$O$22,9,FALSE) -> Please fill out Sensitivity Labels Tab | E13: FALSE | F13: Privacy and external user access | K13: FALSE | L13: Content can be shared with | N13: Content can be shared with: | P13: Use Microsoft Entra Conditional Access to protect labeled SharePoint sites | S13: Private team discoverability
B14: =B13+1 -> 12 | E14: FALSE | F14: External sharing and Conditional Access | I14: Select check box as needed | K14: FALSE | L14: Use Microsoft Entra Conditional Access to protect labeled SharePoint sites | N14: Choose from Drop Down | P14: FALSE | Q14: Determine whether users can access SharePoint sites from unmanaged Devices | S14: FALSE | T14: Allow users to discover private teams that have this label applied.
B15: =B14+1 -> 13 | E15: FALSE | F15: Private teams discoverability and shared channel settings | H15: FALSE | I15: Let Microsoft 365 Group owners add people outside your organization to the group as guests. | S15: Teams shared channels
B16: =B15+1 -> 14 | P16: FALSE | Q16: Choose an existing authentication context. | S16: FALSE | T16: Internal Only
B17: =B16+1 -> 15 | Q17: Enter Text | S17: FALSE | T17: Same label only
B18: =B17+1 -> 16 | S18: FALSE | T18: Private teams only
A22: =A13+1 -> 2 | B22: =B13+10 -> 21 | C22: =VLOOKUP(A22,INputs!$G$3:$O$22,9,FALSE) -> Please fill out Sensitivity Labels Tab | E22: FALSE | F22: Privacy and external user access | K22: FALSE | L22: Content can be shared with | N22: Content can be shared with: | P22: Use Microsoft Entra Conditional Access to protect labeled SharePoint sites | S22: Private team discoverability
B23: =B22+1 -> 22 | E23: FALSE | F23: External sharing and Conditional Access | I23: Select check box as needed | K23: FALSE | L23: Use Microsoft Entra Conditional Access to protect labeled SharePoint sites | N23: Choose from Drop Down | P23: FALSE | Q23: Determine whether users can access SharePoint sites from unmanaged Devices | S23: FALSE | T23: Allow users to discover private teams that have this label applied.
B24: =B23+1 -> 23 | E24: FALSE | F24: Private teams discoverability and shared channel settings | H24: FALSE | I24: Let Microsoft 365 Group owners add people outside your organization to the group as guests. | S24: Teams shared channels
B25: =B24+1 -> 24 | P25: FALSE | Q25: Choose an existing authentication context. | S25: FALSE | T25: Internal Only
B26: =B25+1 -> 25 | Q26: Enter Text | S26: FALSE | T26: Same label only
B27: =B26+1 -> 26 | S27: FALSE | T27: Private teams only
A31: =A22+1 -> 3 | B31: =B22+10 -> 31 | C31: =VLOOKUP(A31,INputs!$G$3:$O$22,9,FALSE) -> Please fill out Sensitivity Labels Tab | E31: FALSE | F31: Privacy and external user access | K31: FALSE | L31: Content can be shared with | N31: Content can be shared with: | P31: Use Microsoft Entra Conditional Access to protect labeled SharePoint sites | S31: Private team discoverability
B32: =B31+1 -> 32 | E32: FALSE | F32: External sharing and Conditional Access | I32: Select check box as needed | K32: FALSE | L32: Use Microsoft Entra Conditional Access to protect labeled SharePoint sites | N32: Choose from Drop Down | P32: FALSE | Q32: Determine whether users can access SharePoint sites from unmanaged Devices | S32: FALSE | T32: Allow users to discover private teams that have this label applied.
B33: =B32+1 -> 33 | E33: FALSE | F33: Private teams discoverability and shared channel settings | H33: FALSE | I33: Let Microsoft 365 Group owners add people outside your organization to the group as guests. | S33: Teams shared channels
B34: =B33+1 -> 34 | P34: FALSE | Q34: Choose an existing authentication context. | S34: FALSE | T34: Internal Only
B35: =B34+1 -> 35 | Q35: Enter Text | S35: FALSE | T35: Same label only
B36: =B35+1 -> 36 | S36: FALSE | T36: Private teams only
A40: =A31+1 -> 4 | B40: =B31+10 -> 41 | C40: =VLOOKUP(A40,INputs!$G$3:$O$22,9,FALSE) -> Please fill out Sensitivity Labels Tab | E40: FALSE | F40: Privacy and external user access | K40: FALSE | L40: Content can be shared with | N40: Content can be shared with: | P40: Use Microsoft Entra Conditional Access to protect labeled SharePoint sites | S40: Private team discoverability
B41: =B40+1 -> 42 | E41: FALSE | F41: External sharing and Conditional Access | I41: Select check box as needed | K41: FALSE | L41: Use Microsoft Entra Conditional Access to protect labeled SharePoint sites | N41: Choose from Drop Down | P41: FALSE | Q41: Determine whether users can access SharePoint sites from unmanaged Devices | S41: FALSE | T41: Allow users to discover private teams that have this label applied.
B42: =B41+1 -> 43 | E42: FALSE | F42: Private teams discoverability and shared channel settings | H42: FALSE | I42: Let Microsoft 365 Group owners add people outside your organization to the group as guests. | S42: Teams shared channels
B43: =B42+1 -> 44 | P43: FALSE | Q43: Choose an existing authentication context. | S43: FALSE | T43: Internal Only
B44: =B43+1 -> 45 | Q44: Enter Text | S44: FALSE | T44: Same label only
B45: =B44+1 -> 46 | S45: FALSE | T45: Private teams only
A49: =A40+1 -> 5 | B49: =B40+10 -> 51 | C49: =VLOOKUP(A49,INputs!$G$3:$O$22,9,FALSE) -> Please fill out Sensitivity Labels Tab | E49: FALSE | F49: Privacy and external user access | K49: FALSE | L49: Content can be shared with | N49: Content can be shared with: | P49: Use Microsoft Entra Conditional Access to protect labeled SharePoint sites | S49: Private team discoverability
